2025-06-23 10:41:14 - INFO  - root() - ルートにアクセスしました
2025-06-23 10:41:14 - DEBUG - get_token_expires() - token expires が存在しません
2025-06-23 10:41:14 - DEBUG - compare_expire_date() - expires が存在しないため、有効期限チェックをスキップ
2025-06-23 10:41:14 - DEBUG - token is not expired.
2025-06-23 10:41:14 - INFO  - 一般ユーザーの二重注文チェック開始 - username: user1
2025-06-23 10:41:14 - INFO  - === 二重注文チェック開始 ===
2025-06-23 10:41:14 - INFO  - Cookieから取得したusername: 'user1'
2025-06-23 10:41:14 - DEBUG - today=datetime.date(2025, 6, 23), username='user1'
2025-06-23 10:41:14 - INFO  - 検索対象日: 2025-06-23 (型: <class 'datetime.date'>)
2025-06-23 10:41:14 - INFO  - 検索対象ユーザー: 'user1'
2025-06-23 10:41:14 - DEBUG - stmt=<sqlalchemy.sql.selectable.Select object at 0x7f46bed10a10>
2025-06-23 10:41:14 - ERROR - SQL実行中にエラーが発生しました:(sqlalchemy.dialects.postgresql.asyncpg.ProgrammingError) <class 'asyncpg.exceptions.UndefinedTableError'>: relation "Orders" does not exist
[SQL: SELECT "Orders".order_id, "Companies".name AS company_name, "Orders".user_id, "Orders".username, "Orders".shop_name, "Menus".name AS menu_name, "Orders".amount, "Orders".created_at, "Orders".expected_delivery_date, "Orders".checked 
FROM "Orders" JOIN "Companies" ON "Orders".company_id = "Companies".company_id JOIN "Menus" ON "Orders".menu_id = "Menus".menu_id 
WHERE "Orders".username = $1::VARCHAR AND "Orders".created_at BETWEEN $2::TIMESTAMP WITHOUT TIME ZONE AND $3::TIMESTAMP WITHOUT TIME ZONE]
[parameters: ('user1', datetime.datetime(2025, 6, 23, 0, 0), datetime.datetime(2025, 6, 23, 23, 59, 59, 999999))]
(Background on this error at: https://sqlalche.me/e/20/f405)
2025-06-23 10:41:14 - DEBUG - today_orders=None
2025-06-23 10:41:14 - INFO  - 検索結果: None
2025-06-23 10:41:14 - INFO  - 取得した注文数: 0
2025-06-23 10:41:14 - DEBUG - 本日の注文は見つかりませんでした
2025-06-23 10:41:14 - INFO  - === 二重注文なし、処理続行 ===
2025-06-23 10:41:14 - INFO  - 二重注文なし。処理を続行します。username: user1
2025-06-23 10:41:14 - WARNING - クエリ実行失敗 (試行 1/3): (sqlalchemy.dialects.postgresql.asyncpg.ProgrammingError) <class 'asyncpg.exceptions.UndefinedTableError'>: relation "Users" does not exist
[SQL: SELECT "Users".user_id, "Users".username, "Users".password, "Users".name, "Users".token, "Users".exp, "Users".company_id, "Users".shop_name, "Users".menu_id, "Users".permission, "Users".is_modified, "Users".created_at, "Users".updated_at 
FROM "Users" 
WHERE "Users".username = $1::VARCHAR]
[parameters: ('user1',)]
(Background on this error at: https://sqlalche.me/e/20/f405)
2025-06-23 10:41:15 - WARNING - クエリ実行失敗 (試行 2/3): (sqlalchemy.dialects.postgresql.asyncpg.Error) <class 'asyncpg.exceptions.InFailedSQLTransactionError'>: current transaction is aborted, commands ignored until end of transaction block
[SQL: SELECT "Users".user_id, "Users".username, "Users".password, "Users".name, "Users".token, "Users".exp, "Users".company_id, "Users".shop_name, "Users".menu_id, "Users".permission, "Users".is_modified, "Users".created_at, "Users".updated_at 
FROM "Users" 
WHERE "Users".username = $1::VARCHAR]
[parameters: ('user1',)]
(Background on this error at: https://sqlalche.me/e/20/dbapi)
2025-06-23 10:41:16 - WARNING - クエリ実行失敗 (試行 3/3): (sqlalchemy.dialects.postgresql.asyncpg.Error) <class 'asyncpg.exceptions.InFailedSQLTransactionError'>: current transaction is aborted, commands ignored until end of transaction block
[SQL: SELECT "Users".user_id, "Users".username, "Users".password, "Users".name, "Users".token, "Users".exp, "Users".company_id, "Users".shop_name, "Users".menu_id, "Users".permission, "Users".is_modified, "Users".created_at, "Users".updated_at 
FROM "Users" 
WHERE "Users".username = $1::VARCHAR]
[parameters: ('user1',)]
(Background on this error at: https://sqlalche.me/e/20/dbapi)
2025-06-23 10:41:16 - ERROR - root() - 予期せぬエラーが発生しました
Traceback (most recent call last):
  File "/usr/local/lib/python3.11/site-packages/sqlalchemy/dialects/postgresql/asyncpg.py", line 521, in _prepare_and_execute
    prepared_stmt, attributes = await adapt_connection._prepare(
                                ^^^^^^^^^^^^^^^^^^^^^^^^^^^^^^^^
  File "/usr/local/lib/python3.11/site-packages/sqlalchemy/dialects/postgresql/asyncpg.py", line 768, in _prepare
    prepared_stmt = await self._connection.prepare(
                    ^^^^^^^^^^^^^^^^^^^^^^^^^^^^^^^
  File "/usr/local/lib/python3.11/site-packages/asyncpg/connection.py", line 635, in prepare
    return await self._prepare(
           ^^^^^^^^^^^^^^^^^^^^
  File "/usr/local/lib/python3.11/site-packages/asyncpg/connection.py", line 653, in _prepare
    stmt = await self._get_statement(
           ^^^^^^^^^^^^^^^^^^^^^^^^^^
  File "/usr/local/lib/python3.11/site-packages/asyncpg/connection.py", line 432, in _get_statement
    statement = await self._protocol.prepare(
                ^^^^^^^^^^^^^^^^^^^^^^^^^^^^^
  File "asyncpg/protocol/protocol.pyx", line 165, in prepare
asyncpg.exceptions.InFailedSQLTransactionError: current transaction is aborted, commands ignored until end of transaction block

The above exception was the direct cause of the following exception:

Traceback (most recent call last):
  File "/usr/local/lib/python3.11/site-packages/sqlalchemy/engine/base.py", line 1963, in _exec_single_context
    self.dialect.do_execute(
  File "/usr/local/lib/python3.11/site-packages/sqlalchemy/engine/default.py", line 943, in do_execute
    cursor.execute(statement, parameters)
  File "/usr/local/lib/python3.11/site-packages/sqlalchemy/dialects/postgresql/asyncpg.py", line 580, in execute
    self._adapt_connection.await_(
  File "/usr/local/lib/python3.11/site-packages/sqlalchemy/util/_concurrency_py3k.py", line 132, in await_only
    return current.parent.switch(awaitable)  # type: ignore[no-any-return,attr-defined] # noqa: E501
           ^^^^^^^^^^^^^^^^^^^^^^^^^^^^^^^^
  File "/usr/local/lib/python3.11/site-packages/sqlalchemy/util/_concurrency_py3k.py", line 196, in greenlet_spawn
    value = await result
            ^^^^^^^^^^^^
  File "/usr/local/lib/python3.11/site-packages/sqlalchemy/dialects/postgresql/asyncpg.py", line 558, in _prepare_and_execute
    self._handle_exception(error)
  File "/usr/local/lib/python3.11/site-packages/sqlalchemy/dialects/postgresql/asyncpg.py", line 508, in _handle_exception
    self._adapt_connection._handle_exception(error)
  File "/usr/local/lib/python3.11/site-packages/sqlalchemy/dialects/postgresql/asyncpg.py", line 792, in _handle_exception
    raise translated_error from error
sqlalchemy.dialects.postgresql.asyncpg.AsyncAdapt_asyncpg_dbapi.Error: <class 'asyncpg.exceptions.InFailedSQLTransactionError'>: current transaction is aborted, commands ignored until end of transaction block

The above exception was the direct cause of the following exception:

Traceback (most recent call last):
  File "/app/main.py", line 174, in root
    user = await get_user(username)
           ^^^^^^^^^^^^^^^^^^^^^^^^
  File "/app/utils/decorator.py", line 19, in async_wrapper
    result = await func(*args, **kwargs)
             ^^^^^^^^^^^^^^^^^^^^^^^^^^^
  File "/app/models/user.py", line 600, in get_user
    result = await execute_with_retry(session, stmt)
             ^^^^^^^^^^^^^^^^^^^^^^^^^^^^^^^^^^^^^^^
  File "/app/models/user.py", line 594, in execute_with_retry
    raise e
  File "/app/models/user.py", line 588, in execute_with_retry
    return await session.execute(stmt)
           ^^^^^^^^^^^^^^^^^^^^^^^^^^^
  File "/usr/local/lib/python3.11/site-packages/sqlalchemy/ext/asyncio/session.py", line 463, in execute
    result = await greenlet_spawn(
             ^^^^^^^^^^^^^^^^^^^^^
  File "/usr/local/lib/python3.11/site-packages/sqlalchemy/util/_concurrency_py3k.py", line 201, in greenlet_spawn
    result = context.throw(*sys.exc_info())
             ^^^^^^^^^^^^^^^^^^^^^^^^^^^^^^
  File "/usr/local/lib/python3.11/site-packages/sqlalchemy/orm/session.py", line 2365, in execute
    return self._execute_internal(
           ^^^^^^^^^^^^^^^^^^^^^^^
  File "/usr/local/lib/python3.11/site-packages/sqlalchemy/orm/session.py", line 2251, in _execute_internal
    result: Result[Any] = compile_state_cls.orm_execute_statement(
                          ^^^^^^^^^^^^^^^^^^^^^^^^^^^^^^^^^^^^^^^^
  File "/usr/local/lib/python3.11/site-packages/sqlalchemy/orm/context.py", line 306, in orm_execute_statement
    result = conn.execute(
             ^^^^^^^^^^^^^
  File "/usr/local/lib/python3.11/site-packages/sqlalchemy/engine/base.py", line 1415, in execute
    return meth(
           ^^^^^
  File "/usr/local/lib/python3.11/site-packages/sqlalchemy/sql/elements.py", line 523, in _execute_on_connection
    return connection._execute_clauseelement(
           ^^^^^^^^^^^^^^^^^^^^^^^^^^^^^^^^^^
  File "/usr/local/lib/python3.11/site-packages/sqlalchemy/engine/base.py", line 1637, in _execute_clauseelement
    ret = self._execute_context(
          ^^^^^^^^^^^^^^^^^^^^^^
  File "/usr/local/lib/python3.11/site-packages/sqlalchemy/engine/base.py", line 1842, in _execute_context
    return self._exec_single_context(
           ^^^^^^^^^^^^^^^^^^^^^^^^^^
  File "/usr/local/lib/python3.11/site-packages/sqlalchemy/engine/base.py", line 1982, in _exec_single_context
    self._handle_dbapi_exception(
  File "/usr/local/lib/python3.11/site-packages/sqlalchemy/engine/base.py", line 2351, in _handle_dbapi_exception
    raise sqlalchemy_exception.with_traceback(exc_info[2]) from e
  File "/usr/local/lib/python3.11/site-packages/sqlalchemy/engine/base.py", line 1963, in _exec_single_context
    self.dialect.do_execute(
  File "/usr/local/lib/python3.11/site-packages/sqlalchemy/engine/default.py", line 943, in do_execute
    cursor.execute(statement, parameters)
  File "/usr/local/lib/python3.11/site-packages/sqlalchemy/dialects/postgresql/asyncpg.py", line 580, in execute
    self._adapt_connection.await_(
  File "/usr/local/lib/python3.11/site-packages/sqlalchemy/util/_concurrency_py3k.py", line 132, in await_only
    return current.parent.switch(awaitable)  # type: ignore[no-any-return,attr-defined] # noqa: E501
           ^^^^^^^^^^^^^^^^^^^^^^^^^^^^^^^^
  File "/usr/local/lib/python3.11/site-packages/sqlalchemy/util/_concurrency_py3k.py", line 196, in greenlet_spawn
    value = await result
            ^^^^^^^^^^^^
  File "/usr/local/lib/python3.11/site-packages/sqlalchemy/dialects/postgresql/asyncpg.py", line 558, in _prepare_and_execute
    self._handle_exception(error)
  File "/usr/local/lib/python3.11/site-packages/sqlalchemy/dialects/postgresql/asyncpg.py", line 508, in _handle_exception
    self._adapt_connection._handle_exception(error)
  File "/usr/local/lib/python3.11/site-packages/sqlalchemy/dialects/postgresql/asyncpg.py", line 792, in _handle_exception
    raise translated_error from error
sqlalchemy.exc.DBAPIError: (sqlalchemy.dialects.postgresql.asyncpg.Error) <class 'asyncpg.exceptions.InFailedSQLTransactionError'>: current transaction is aborted, commands ignored until end of transaction block
[SQL: SELECT "Users".user_id, "Users".username, "Users".password, "Users".name, "Users".token, "Users".exp, "Users".company_id, "Users".shop_name, "Users".menu_id, "Users".permission, "Users".is_modified, "Users".created_at, "Users".updated_at 
FROM "Users" 
WHERE "Users".username = $1::VARCHAR]
[parameters: ('user1',)]
(Background on this error at: https://sqlalche.me/e/20/dbapi)
2025-06-23 10:41:16 - INFO  - Redirect Login Failure - 予期せぬエラーが発生しました: (sqlalchemy.dialects.postgresql.asyncpg.Error) <class 'asyncpg.exceptions.InFailedSQLTransactionError'>: current transaction is aborted, commands ignored until end of transaction block
[SQL: SELECT "Users".user_id, "Users".username, "Users".password, "Users".name, "Users".token, "Users".exp, "Users".company_id, "Users".shop_name, "Users".menu_id, "Users".permission, "Users".is_modified, "Users".created_at, "Users".updated_at 
FROM "Users" 
WHERE "Users".username = $1::VARCHAR]
[parameters: ('user1',)]
(Background on this error at: https://sqlalche.me/e/20/dbapi)
2025-06-23 10:41:16 - ERROR - Error detail: []
