2025-03-12 13:49:08 - INFO - Started server process [15536]
2025-03-12 13:49:08 - INFO - Waiting for application startup.
2025-03-12 13:49:08 - INFO - Application startup complete.
2025-03-12 13:49:08 - INFO - Uvicorn running on https://192.168.3.19:8000 (Press CTRL+C to quit)
2025-03-12 13:49:10 - INFO - root() - ルートにアクセスしました
2025-03-12 13:49:10 - DEBUG - token_result: ('eyJhbGciOiJIUzI1NiIsInR5cCI6IkpXVCJ9.eyJzdWIiOiJ1c2VyMSIsInBlcm1pc3Npb24iOjEsImV4cCI6MTc0MjE4NTMzOH0.VBJGQV2zxNg72PcrE3Zcfsqm9tSWDaHYNladSb_DZYU', '1742185338')
2025-03-12 13:49:10 - ERROR - Exception in ASGI application
Traceback (most recent call last):
  File "C:\Users\tensy\AppData\Local\Programs\Python\Python312\Lib\site-packages\uvicorn\protocols\http\h11_impl.py", line 403, in run_asgi
    result = await app(  # type: ignore[func-returns-value]
             ^^^^^^^^^^^^^^^^^^^^^^^^^^^^^^^^^^^^^^^^^^^^^^
  File "C:\Users\tensy\AppData\Local\Programs\Python\Python312\Lib\site-packages\uvicorn\middleware\proxy_headers.py", line 60, in __call__
    return await self.app(scope, receive, send)
           ^^^^^^^^^^^^^^^^^^^^^^^^^^^^^^^^^^^^
  File "C:\Users\tensy\AppData\Local\Programs\Python\Python312\Lib\site-packages\fastapi\applications.py", line 1054, in __call__
    await super().__call__(scope, receive, send)
  File "C:\Users\tensy\AppData\Local\Programs\Python\Python312\Lib\site-packages\starlette\applications.py", line 113, in __call__
    await self.middleware_stack(scope, receive, send)
  File "C:\Users\tensy\AppData\Local\Programs\Python\Python312\Lib\site-packages\starlette\middleware\errors.py", line 187, in __call__
    raise exc
  File "C:\Users\tensy\AppData\Local\Programs\Python\Python312\Lib\site-packages\starlette\middleware\errors.py", line 165, in __call__
    await self.app(scope, receive, _send)
  File "C:\Users\tensy\AppData\Local\Programs\Python\Python312\Lib\site-packages\starlette\middleware\exceptions.py", line 62, in __call__
    await wrap_app_handling_exceptions(self.app, conn)(scope, receive, send)
  File "C:\Users\tensy\AppData\Local\Programs\Python\Python312\Lib\site-packages\starlette\_exception_handler.py", line 53, in wrapped_app
    raise exc
  File "C:\Users\tensy\AppData\Local\Programs\Python\Python312\Lib\site-packages\starlette\_exception_handler.py", line 42, in wrapped_app
    await app(scope, receive, sender)
  File "C:\Users\tensy\AppData\Local\Programs\Python\Python312\Lib\site-packages\starlette\routing.py", line 715, in __call__
    await self.middleware_stack(scope, receive, send)
  File "C:\Users\tensy\AppData\Local\Programs\Python\Python312\Lib\site-packages\starlette\routing.py", line 735, in app
    await route.handle(scope, receive, send)
  File "C:\Users\tensy\AppData\Local\Programs\Python\Python312\Lib\site-packages\starlette\routing.py", line 288, in handle
    await self.app(scope, receive, send)
  File "C:\Users\tensy\AppData\Local\Programs\Python\Python312\Lib\site-packages\starlette\routing.py", line 76, in app
    await wrap_app_handling_exceptions(app, request)(scope, receive, send)
  File "C:\Users\tensy\AppData\Local\Programs\Python\Python312\Lib\site-packages\starlette\_exception_handler.py", line 53, in wrapped_app
    raise exc
  File "C:\Users\tensy\AppData\Local\Programs\Python\Python312\Lib\site-packages\starlette\_exception_handler.py", line 42, in wrapped_app
    await app(scope, receive, sender)
  File "C:\Users\tensy\AppData\Local\Programs\Python\Python312\Lib\site-packages\starlette\routing.py", line 73, in app
    response = await f(request)
               ^^^^^^^^^^^^^^^^
  File "C:\Users\tensy\AppData\Local\Programs\Python\Python312\Lib\site-packages\fastapi\routing.py", line 301, in app
    raw_response = await run_endpoint_function(
                   ^^^^^^^^^^^^^^^^^^^^^^^^^^^^
  File "C:\Users\tensy\AppData\Local\Programs\Python\Python312\Lib\site-packages\fastapi\routing.py", line 212, in run_endpoint_function
    return await dependant.call(**values)
           ^^^^^^^^^^^^^^^^^^^^^^^^^^^^^^
  File "C:\Obento-Test\v_0.1.6\app\utils\utils.py", line 19, in async_wrapper
    result = await func(*args, **kwargs)
             ^^^^^^^^^^^^^^^^^^^^^^^^^^^
  File "C:\Obento-Test\v_0.1.6\app\main.py", line 114, in root
    if compare_expire_date(exp):
       ^^^^^^^^^^^^^^^^^^^^^^^^
  File "C:\Obento-Test\v_0.1.6\app\utils\utils.py", line 28, in sync_wrapper
    result = func(*args, **kwargs)
             ^^^^^^^^^^^^^^^^^^^^^
  File "C:\Obento-Test\v_0.1.6\app\utils\utils.py", line 186, in compare_expire_date
    max_age = convert_expires_to_max_age(exp_unix_str)
              ^^^^^^^^^^^^^^^^^^^^^^^^^^^^^^^^^^^^^^^^
  File "C:\Obento-Test\v_0.1.6\app\utils\utils.py", line 292, in convert_expires_to_max_age
    expires_datetime = datetime.fromisoformat(expires).replace(tzinfo=timezone.utc)
                       ^^^^^^^^^^^^^^^^^^^^^^^^^^^^^^^
ValueError: Invalid isoformat string: '1742185338'
2025-03-12 13:49:40 - INFO - root() - ルートにアクセスしました
2025-03-12 13:49:40 - DEBUG - token_result: None
2025-03-12 13:49:40 - DEBUG - token_result: ありません
2025-03-12 13:49:44 - INFO - root() - ルートにアクセスしました
2025-03-12 13:49:44 - DEBUG - token_result: ('eyJhbGciOiJIUzI1NiIsInR5cCI6IkpXVCJ9.eyJzdWIiOiJ1c2VyMSIsInBlcm1pc3Npb24iOjEsImV4cCI6MTc0MjE4NTMzOH0.VBJGQV2zxNg72PcrE3Zcfsqm9tSWDaHYNladSb_DZYU', '1742185338')
2025-03-12 13:49:44 - ERROR - Exception in ASGI application
Traceback (most recent call last):
  File "C:\Users\tensy\AppData\Local\Programs\Python\Python312\Lib\site-packages\uvicorn\protocols\http\h11_impl.py", line 403, in run_asgi
    result = await app(  # type: ignore[func-returns-value]
             ^^^^^^^^^^^^^^^^^^^^^^^^^^^^^^^^^^^^^^^^^^^^^^
  File "C:\Users\tensy\AppData\Local\Programs\Python\Python312\Lib\site-packages\uvicorn\middleware\proxy_headers.py", line 60, in __call__
    return await self.app(scope, receive, send)
           ^^^^^^^^^^^^^^^^^^^^^^^^^^^^^^^^^^^^
  File "C:\Users\tensy\AppData\Local\Programs\Python\Python312\Lib\site-packages\fastapi\applications.py", line 1054, in __call__
    await super().__call__(scope, receive, send)
  File "C:\Users\tensy\AppData\Local\Programs\Python\Python312\Lib\site-packages\starlette\applications.py", line 113, in __call__
    await self.middleware_stack(scope, receive, send)
  File "C:\Users\tensy\AppData\Local\Programs\Python\Python312\Lib\site-packages\starlette\middleware\errors.py", line 187, in __call__
    raise exc
  File "C:\Users\tensy\AppData\Local\Programs\Python\Python312\Lib\site-packages\starlette\middleware\errors.py", line 165, in __call__
    await self.app(scope, receive, _send)
  File "C:\Users\tensy\AppData\Local\Programs\Python\Python312\Lib\site-packages\starlette\middleware\exceptions.py", line 62, in __call__
    await wrap_app_handling_exceptions(self.app, conn)(scope, receive, send)
  File "C:\Users\tensy\AppData\Local\Programs\Python\Python312\Lib\site-packages\starlette\_exception_handler.py", line 53, in wrapped_app
    raise exc
  File "C:\Users\tensy\AppData\Local\Programs\Python\Python312\Lib\site-packages\starlette\_exception_handler.py", line 42, in wrapped_app
    await app(scope, receive, sender)
  File "C:\Users\tensy\AppData\Local\Programs\Python\Python312\Lib\site-packages\starlette\routing.py", line 715, in __call__
    await self.middleware_stack(scope, receive, send)
  File "C:\Users\tensy\AppData\Local\Programs\Python\Python312\Lib\site-packages\starlette\routing.py", line 735, in app
    await route.handle(scope, receive, send)
  File "C:\Users\tensy\AppData\Local\Programs\Python\Python312\Lib\site-packages\starlette\routing.py", line 288, in handle
    await self.app(scope, receive, send)
  File "C:\Users\tensy\AppData\Local\Programs\Python\Python312\Lib\site-packages\starlette\routing.py", line 76, in app
    await wrap_app_handling_exceptions(app, request)(scope, receive, send)
  File "C:\Users\tensy\AppData\Local\Programs\Python\Python312\Lib\site-packages\starlette\_exception_handler.py", line 53, in wrapped_app
    raise exc
  File "C:\Users\tensy\AppData\Local\Programs\Python\Python312\Lib\site-packages\starlette\_exception_handler.py", line 42, in wrapped_app
    await app(scope, receive, sender)
  File "C:\Users\tensy\AppData\Local\Programs\Python\Python312\Lib\site-packages\starlette\routing.py", line 73, in app
    response = await f(request)
               ^^^^^^^^^^^^^^^^
  File "C:\Users\tensy\AppData\Local\Programs\Python\Python312\Lib\site-packages\fastapi\routing.py", line 301, in app
    raw_response = await run_endpoint_function(
                   ^^^^^^^^^^^^^^^^^^^^^^^^^^^^
  File "C:\Users\tensy\AppData\Local\Programs\Python\Python312\Lib\site-packages\fastapi\routing.py", line 212, in run_endpoint_function
    return await dependant.call(**values)
           ^^^^^^^^^^^^^^^^^^^^^^^^^^^^^^
  File "C:\Obento-Test\v_0.1.6\app\utils\utils.py", line 19, in async_wrapper
    result = await func(*args, **kwargs)
             ^^^^^^^^^^^^^^^^^^^^^^^^^^^
  File "C:\Obento-Test\v_0.1.6\app\main.py", line 114, in root
    if compare_expire_date(exp):
       ^^^^^^^^^^^^^^^^^^^^^^^^
  File "C:\Obento-Test\v_0.1.6\app\utils\utils.py", line 28, in sync_wrapper
    result = func(*args, **kwargs)
             ^^^^^^^^^^^^^^^^^^^^^
  File "C:\Obento-Test\v_0.1.6\app\utils\utils.py", line 186, in compare_expire_date
    max_age = convert_expires_to_max_age(exp_unix_str)
              ^^^^^^^^^^^^^^^^^^^^^^^^^^^^^^^^^^^^^^^^
  File "C:\Obento-Test\v_0.1.6\app\utils\utils.py", line 292, in convert_expires_to_max_age
    expires_datetime = datetime.fromisoformat(expires).replace(tzinfo=timezone.utc)
                       ^^^^^^^^^^^^^^^^^^^^^^^^^^^^^^^
ValueError: Invalid isoformat string: '1742185338'
2025-03-12 13:50:14 - INFO - root() - ルートにアクセスしました
2025-03-12 13:50:14 - DEBUG - token_result: None
2025-03-12 13:50:14 - DEBUG - token_result: ありません
2025-03-12 13:50:21 - INFO - root() - ルートにアクセスしました
2025-03-12 13:50:21 - DEBUG - token_result: None
2025-03-12 13:50:21 - DEBUG - token_result: ありません
2025-03-12 13:50:23 - INFO - root() - ルートにアクセスしました
2025-03-12 13:50:23 - DEBUG - token_result: None
2025-03-12 13:50:23 - DEBUG - token_result: ありません
2025-03-12 13:50:23 - INFO - root() - ルートにアクセスしました
2025-03-12 13:50:23 - DEBUG - token_result: None
2025-03-12 13:50:23 - DEBUG - token_result: ありません
2025-03-12 13:50:23 - INFO - root() - ルートにアクセスしました
2025-03-12 13:50:23 - DEBUG - token_result: None
2025-03-12 13:50:23 - DEBUG - token_result: ありません
2025-03-12 13:50:24 - INFO - root() - ルートにアクセスしました
2025-03-12 13:50:24 - DEBUG - token_result: None
2025-03-12 13:50:24 - DEBUG - token_result: ありません
2025-03-12 13:51:19 - INFO - root() - ルートにアクセスしました
2025-03-12 13:51:19 - DEBUG - token_result: None
2025-03-12 13:51:19 - DEBUG - token_result: ありません
2025-03-12 13:51:42 - INFO - Started server process [5276]
2025-03-12 13:51:42 - INFO - Waiting for application startup.
2025-03-12 13:51:42 - INFO - Application startup complete.
2025-03-12 13:51:42 - INFO - Uvicorn running on https://192.168.3.19:8000 (Press CTRL+C to quit)
2025-03-12 13:51:43 - INFO - root() - ルートにアクセスしました
2025-03-12 13:51:43 - DEBUG - token_result: None
2025-03-12 13:51:43 - DEBUG - token_result: ありません
2025-03-12 13:51:44 - INFO - root() - ルートにアクセスしました
2025-03-12 13:51:44 - DEBUG - token_result: None
2025-03-12 13:51:44 - DEBUG - token_result: ありません
2025-03-12 13:51:44 - INFO - root() - ルートにアクセスしました
2025-03-12 13:51:44 - DEBUG - token_result: ('eyJhbGciOiJIUzI1NiIsInR5cCI6IkpXVCJ9.eyJzdWIiOiJ1c2VyMSIsInBlcm1pc3Npb24iOjEsImV4cCI6MTc0MjE4NTMzOH0.VBJGQV2zxNg72PcrE3Zcfsqm9tSWDaHYNladSb_DZYU', '1742185338')
2025-03-12 13:51:44 - ERROR - Exception in ASGI application
Traceback (most recent call last):
  File "C:\Users\tensy\AppData\Local\Programs\Python\Python312\Lib\site-packages\uvicorn\protocols\http\h11_impl.py", line 403, in run_asgi
    result = await app(  # type: ignore[func-returns-value]
             ^^^^^^^^^^^^^^^^^^^^^^^^^^^^^^^^^^^^^^^^^^^^^^
  File "C:\Users\tensy\AppData\Local\Programs\Python\Python312\Lib\site-packages\uvicorn\middleware\proxy_headers.py", line 60, in __call__
    return await self.app(scope, receive, send)
           ^^^^^^^^^^^^^^^^^^^^^^^^^^^^^^^^^^^^
  File "C:\Users\tensy\AppData\Local\Programs\Python\Python312\Lib\site-packages\fastapi\applications.py", line 1054, in __call__
    await super().__call__(scope, receive, send)
  File "C:\Users\tensy\AppData\Local\Programs\Python\Python312\Lib\site-packages\starlette\applications.py", line 113, in __call__
    await self.middleware_stack(scope, receive, send)
  File "C:\Users\tensy\AppData\Local\Programs\Python\Python312\Lib\site-packages\starlette\middleware\errors.py", line 187, in __call__
    raise exc
  File "C:\Users\tensy\AppData\Local\Programs\Python\Python312\Lib\site-packages\starlette\middleware\errors.py", line 165, in __call__
    await self.app(scope, receive, _send)
  File "C:\Users\tensy\AppData\Local\Programs\Python\Python312\Lib\site-packages\starlette\middleware\exceptions.py", line 62, in __call__
    await wrap_app_handling_exceptions(self.app, conn)(scope, receive, send)
  File "C:\Users\tensy\AppData\Local\Programs\Python\Python312\Lib\site-packages\starlette\_exception_handler.py", line 53, in wrapped_app
    raise exc
  File "C:\Users\tensy\AppData\Local\Programs\Python\Python312\Lib\site-packages\starlette\_exception_handler.py", line 42, in wrapped_app
    await app(scope, receive, sender)
  File "C:\Users\tensy\AppData\Local\Programs\Python\Python312\Lib\site-packages\starlette\routing.py", line 715, in __call__
    await self.middleware_stack(scope, receive, send)
  File "C:\Users\tensy\AppData\Local\Programs\Python\Python312\Lib\site-packages\starlette\routing.py", line 735, in app
    await route.handle(scope, receive, send)
  File "C:\Users\tensy\AppData\Local\Programs\Python\Python312\Lib\site-packages\starlette\routing.py", line 288, in handle
    await self.app(scope, receive, send)
  File "C:\Users\tensy\AppData\Local\Programs\Python\Python312\Lib\site-packages\starlette\routing.py", line 76, in app
    await wrap_app_handling_exceptions(app, request)(scope, receive, send)
  File "C:\Users\tensy\AppData\Local\Programs\Python\Python312\Lib\site-packages\starlette\_exception_handler.py", line 53, in wrapped_app
    raise exc
  File "C:\Users\tensy\AppData\Local\Programs\Python\Python312\Lib\site-packages\starlette\_exception_handler.py", line 42, in wrapped_app
    await app(scope, receive, sender)
  File "C:\Users\tensy\AppData\Local\Programs\Python\Python312\Lib\site-packages\starlette\routing.py", line 73, in app
    response = await f(request)
               ^^^^^^^^^^^^^^^^
  File "C:\Users\tensy\AppData\Local\Programs\Python\Python312\Lib\site-packages\fastapi\routing.py", line 301, in app
    raw_response = await run_endpoint_function(
                   ^^^^^^^^^^^^^^^^^^^^^^^^^^^^
  File "C:\Users\tensy\AppData\Local\Programs\Python\Python312\Lib\site-packages\fastapi\routing.py", line 212, in run_endpoint_function
    return await dependant.call(**values)
           ^^^^^^^^^^^^^^^^^^^^^^^^^^^^^^
  File "C:\Obento-Test\v_0.1.6\app\utils\utils.py", line 19, in async_wrapper
    result = await func(*args, **kwargs)
             ^^^^^^^^^^^^^^^^^^^^^^^^^^^
  File "C:\Obento-Test\v_0.1.6\app\main.py", line 114, in root
    if compare_expire_date(exp):
       ^^^^^^^^^^^^^^^^^^^^^^^^
  File "C:\Obento-Test\v_0.1.6\app\utils\utils.py", line 28, in sync_wrapper
    result = func(*args, **kwargs)
             ^^^^^^^^^^^^^^^^^^^^^
  File "C:\Obento-Test\v_0.1.6\app\utils\utils.py", line 186, in compare_expire_date
    max_age = convert_expires_to_max_age(exp_unix_str)
              ^^^^^^^^^^^^^^^^^^^^^^^^^^^^^^^^^^^^^^^^
  File "C:\Obento-Test\v_0.1.6\app\utils\utils.py", line 292, in convert_expires_to_max_age
    expires_datetime = datetime.fromisoformat(expires).replace(tzinfo=timezone.utc)
                       ^^^^^^^^^^^^^^^^^^^^^^^^^^^^^^^
ValueError: Invalid isoformat string: '1742185338'
2025-03-12 13:52:01 - INFO - root() - ルートにアクセスしました
2025-03-12 13:52:01 - DEBUG - token_result: None
2025-03-12 13:52:01 - DEBUG - token_result: ありません
2025-03-12 13:53:10 - INFO - Started server process [3796]
2025-03-12 13:53:10 - INFO - Waiting for application startup.
2025-03-12 13:53:10 - INFO - Application startup complete.
2025-03-12 13:53:10 - INFO - Uvicorn running on https://192.168.3.19:8000 (Press CTRL+C to quit)
2025-03-12 13:53:11 - INFO - root() - ルートにアクセスしました
2025-03-12 13:53:11 - DEBUG - token_result: ('eyJhbGciOiJIUzI1NiIsInR5cCI6IkpXVCJ9.eyJzdWIiOiJ1c2VyMSIsInBlcm1pc3Npb24iOjEsImV4cCI6MTc0MjE4NTMzOH0.VBJGQV2zxNg72PcrE3Zcfsqm9tSWDaHYNladSb_DZYU', '1742185338')
2025-03-12 13:53:12 - ERROR - Exception in ASGI application
Traceback (most recent call last):
  File "C:\Users\tensy\AppData\Local\Programs\Python\Python312\Lib\site-packages\uvicorn\protocols\http\h11_impl.py", line 403, in run_asgi
    result = await app(  # type: ignore[func-returns-value]
             ^^^^^^^^^^^^^^^^^^^^^^^^^^^^^^^^^^^^^^^^^^^^^^
  File "C:\Users\tensy\AppData\Local\Programs\Python\Python312\Lib\site-packages\uvicorn\middleware\proxy_headers.py", line 60, in __call__
    return await self.app(scope, receive, send)
           ^^^^^^^^^^^^^^^^^^^^^^^^^^^^^^^^^^^^
  File "C:\Users\tensy\AppData\Local\Programs\Python\Python312\Lib\site-packages\fastapi\applications.py", line 1054, in __call__
    await super().__call__(scope, receive, send)
  File "C:\Users\tensy\AppData\Local\Programs\Python\Python312\Lib\site-packages\starlette\applications.py", line 113, in __call__
    await self.middleware_stack(scope, receive, send)
  File "C:\Users\tensy\AppData\Local\Programs\Python\Python312\Lib\site-packages\starlette\middleware\errors.py", line 187, in __call__
    raise exc
  File "C:\Users\tensy\AppData\Local\Programs\Python\Python312\Lib\site-packages\starlette\middleware\errors.py", line 165, in __call__
    await self.app(scope, receive, _send)
  File "C:\Users\tensy\AppData\Local\Programs\Python\Python312\Lib\site-packages\starlette\middleware\exceptions.py", line 62, in __call__
    await wrap_app_handling_exceptions(self.app, conn)(scope, receive, send)
  File "C:\Users\tensy\AppData\Local\Programs\Python\Python312\Lib\site-packages\starlette\_exception_handler.py", line 53, in wrapped_app
    raise exc
  File "C:\Users\tensy\AppData\Local\Programs\Python\Python312\Lib\site-packages\starlette\_exception_handler.py", line 42, in wrapped_app
    await app(scope, receive, sender)
  File "C:\Users\tensy\AppData\Local\Programs\Python\Python312\Lib\site-packages\starlette\routing.py", line 715, in __call__
    await self.middleware_stack(scope, receive, send)
  File "C:\Users\tensy\AppData\Local\Programs\Python\Python312\Lib\site-packages\starlette\routing.py", line 735, in app
    await route.handle(scope, receive, send)
  File "C:\Users\tensy\AppData\Local\Programs\Python\Python312\Lib\site-packages\starlette\routing.py", line 288, in handle
    await self.app(scope, receive, send)
  File "C:\Users\tensy\AppData\Local\Programs\Python\Python312\Lib\site-packages\starlette\routing.py", line 76, in app
    await wrap_app_handling_exceptions(app, request)(scope, receive, send)
  File "C:\Users\tensy\AppData\Local\Programs\Python\Python312\Lib\site-packages\starlette\_exception_handler.py", line 53, in wrapped_app
    raise exc
  File "C:\Users\tensy\AppData\Local\Programs\Python\Python312\Lib\site-packages\starlette\_exception_handler.py", line 42, in wrapped_app
    await app(scope, receive, sender)
  File "C:\Users\tensy\AppData\Local\Programs\Python\Python312\Lib\site-packages\starlette\routing.py", line 73, in app
    response = await f(request)
               ^^^^^^^^^^^^^^^^
  File "C:\Users\tensy\AppData\Local\Programs\Python\Python312\Lib\site-packages\fastapi\routing.py", line 301, in app
    raw_response = await run_endpoint_function(
                   ^^^^^^^^^^^^^^^^^^^^^^^^^^^^
  File "C:\Users\tensy\AppData\Local\Programs\Python\Python312\Lib\site-packages\fastapi\routing.py", line 212, in run_endpoint_function
    return await dependant.call(**values)
           ^^^^^^^^^^^^^^^^^^^^^^^^^^^^^^
  File "C:\Obento-Test\v_0.1.6\app\utils\utils.py", line 19, in async_wrapper
    result = await func(*args, **kwargs)
             ^^^^^^^^^^^^^^^^^^^^^^^^^^^
  File "C:\Obento-Test\v_0.1.6\app\main.py", line 113, in root
    if compare_expire_date(exp):
       ^^^^^^^^^^^^^^^^^^^^^^^^
  File "C:\Obento-Test\v_0.1.6\app\utils\utils.py", line 28, in sync_wrapper
    result = func(*args, **kwargs)
             ^^^^^^^^^^^^^^^^^^^^^
  File "C:\Obento-Test\v_0.1.6\app\utils\utils.py", line 186, in compare_expire_date
    max_age = convert_expires_to_max_age(exp_unix_str)
              ^^^^^^^^^^^^^^^^^^^^^^^^^^^^^^^^^^^^^^^^
  File "C:\Obento-Test\v_0.1.6\app\utils\utils.py", line 289, in convert_expires_to_max_age
    current_utc_time = datetime.now(timezone.utc)
                       ^^^^^^^^
UnboundLocalError: cannot access local variable 'datetime' where it is not associated with a value
2025-03-12 13:54:47 - INFO - Started server process [2952]
2025-03-12 13:54:47 - INFO - Waiting for application startup.
2025-03-12 13:54:47 - INFO - Application startup complete.
2025-03-12 13:54:47 - INFO - Uvicorn running on https://192.168.3.19:8000 (Press CTRL+C to quit)
2025-03-12 13:54:48 - INFO - root() - ルートにアクセスしました
2025-03-12 13:54:48 - DEBUG - token_result: ('eyJhbGciOiJIUzI1NiIsInR5cCI6IkpXVCJ9.eyJzdWIiOiJ1c2VyMSIsInBlcm1pc3Npb24iOjEsImV4cCI6MTc0MjE4NTMzOH0.VBJGQV2zxNg72PcrE3Zcfsqm9tSWDaHYNladSb_DZYU', '1742185338')
2025-03-12 13:54:49 - ERROR - Exception in ASGI application
Traceback (most recent call last):
  File "C:\Users\tensy\AppData\Local\Programs\Python\Python312\Lib\site-packages\uvicorn\protocols\http\h11_impl.py", line 403, in run_asgi
    result = await app(  # type: ignore[func-returns-value]
             ^^^^^^^^^^^^^^^^^^^^^^^^^^^^^^^^^^^^^^^^^^^^^^
  File "C:\Users\tensy\AppData\Local\Programs\Python\Python312\Lib\site-packages\uvicorn\middleware\proxy_headers.py", line 60, in __call__
    return await self.app(scope, receive, send)
           ^^^^^^^^^^^^^^^^^^^^^^^^^^^^^^^^^^^^
  File "C:\Users\tensy\AppData\Local\Programs\Python\Python312\Lib\site-packages\fastapi\applications.py", line 1054, in __call__
    await super().__call__(scope, receive, send)
  File "C:\Users\tensy\AppData\Local\Programs\Python\Python312\Lib\site-packages\starlette\applications.py", line 113, in __call__
    await self.middleware_stack(scope, receive, send)
  File "C:\Users\tensy\AppData\Local\Programs\Python\Python312\Lib\site-packages\starlette\middleware\errors.py", line 187, in __call__
    raise exc
  File "C:\Users\tensy\AppData\Local\Programs\Python\Python312\Lib\site-packages\starlette\middleware\errors.py", line 165, in __call__
    await self.app(scope, receive, _send)
  File "C:\Users\tensy\AppData\Local\Programs\Python\Python312\Lib\site-packages\starlette\middleware\exceptions.py", line 62, in __call__
    await wrap_app_handling_exceptions(self.app, conn)(scope, receive, send)
  File "C:\Users\tensy\AppData\Local\Programs\Python\Python312\Lib\site-packages\starlette\_exception_handler.py", line 53, in wrapped_app
    raise exc
  File "C:\Users\tensy\AppData\Local\Programs\Python\Python312\Lib\site-packages\starlette\_exception_handler.py", line 42, in wrapped_app
    await app(scope, receive, sender)
  File "C:\Users\tensy\AppData\Local\Programs\Python\Python312\Lib\site-packages\starlette\routing.py", line 715, in __call__
    await self.middleware_stack(scope, receive, send)
  File "C:\Users\tensy\AppData\Local\Programs\Python\Python312\Lib\site-packages\starlette\routing.py", line 735, in app
    await route.handle(scope, receive, send)
  File "C:\Users\tensy\AppData\Local\Programs\Python\Python312\Lib\site-packages\starlette\routing.py", line 288, in handle
    await self.app(scope, receive, send)
  File "C:\Users\tensy\AppData\Local\Programs\Python\Python312\Lib\site-packages\starlette\routing.py", line 76, in app
    await wrap_app_handling_exceptions(app, request)(scope, receive, send)
  File "C:\Users\tensy\AppData\Local\Programs\Python\Python312\Lib\site-packages\starlette\_exception_handler.py", line 53, in wrapped_app
    raise exc
  File "C:\Users\tensy\AppData\Local\Programs\Python\Python312\Lib\site-packages\starlette\_exception_handler.py", line 42, in wrapped_app
    await app(scope, receive, sender)
  File "C:\Users\tensy\AppData\Local\Programs\Python\Python312\Lib\site-packages\starlette\routing.py", line 73, in app
    response = await f(request)
               ^^^^^^^^^^^^^^^^
  File "C:\Users\tensy\AppData\Local\Programs\Python\Python312\Lib\site-packages\fastapi\routing.py", line 301, in app
    raw_response = await run_endpoint_function(
                   ^^^^^^^^^^^^^^^^^^^^^^^^^^^^
  File "C:\Users\tensy\AppData\Local\Programs\Python\Python312\Lib\site-packages\fastapi\routing.py", line 212, in run_endpoint_function
    return await dependant.call(**values)
           ^^^^^^^^^^^^^^^^^^^^^^^^^^^^^^
  File "C:\Obento-Test\v_0.1.6\app\utils\utils.py", line 19, in async_wrapper
    result = await func(*args, **kwargs)
             ^^^^^^^^^^^^^^^^^^^^^^^^^^^
  File "C:\Obento-Test\v_0.1.6\app\main.py", line 113, in root
    if compare_expire_date(exp):
       ^^^^^^^^^^^^^^^^^^^^^^^^
  File "C:\Obento-Test\v_0.1.6\app\utils\utils.py", line 28, in sync_wrapper
    result = func(*args, **kwargs)
             ^^^^^^^^^^^^^^^^^^^^^
  File "C:\Obento-Test\v_0.1.6\app\utils\utils.py", line 186, in compare_expire_date
    max_age = convert_expires_to_max_age(exp_unix_str)
              ^^^^^^^^^^^^^^^^^^^^^^^^^^^^^^^^^^^^^^^^
  File "C:\Obento-Test\v_0.1.6\app\utils\utils.py", line 297, in convert_expires_to_max_age
    expires_datetime = parser.isoparse(expires).replace(tzinfo=timezone.utc)
                       ^^^^^^^^^^^^^^^^^^^^^^^^
  File "C:\Users\tensy\AppData\Local\Programs\Python\Python312\Lib\site-packages\dateutil\parser\isoparser.py", line 37, in func
    return f(self, str_in, *args, **kwargs)
           ^^^^^^^^^^^^^^^^^^^^^^^^^^^^^^^^
  File "C:\Users\tensy\AppData\Local\Programs\Python\Python312\Lib\site-packages\dateutil\parser\isoparser.py", line 138, in isoparse
    components += self._parse_isotime(dt_str[pos + 1:])
                  ^^^^^^^^^^^^^^^^^^^^^^^^^^^^^^^^^^^^^
  File "C:\Users\tensy\AppData\Local\Programs\Python\Python312\Lib\site-packages\dateutil\parser\isoparser.py", line 337, in _parse_isotime
    raise ValueError('ISO time too short')
ValueError: ISO time too short
2025-03-12 13:54:53 - INFO - root() - ルートにアクセスしました
2025-03-12 13:54:53 - DEBUG - token_result: None
2025-03-12 13:54:53 - DEBUG - token_result: ありません
2025-03-12 14:02:50 - INFO - Started server process [3796]
2025-03-12 14:02:50 - INFO - Waiting for application startup.
2025-03-12 14:02:50 - INFO - Application startup complete.
2025-03-12 14:02:50 - INFO - Uvicorn running on https://192.168.3.19:8000 (Press CTRL+C to quit)
2025-03-12 14:02:51 - INFO - root() - ルートにアクセスしました
2025-03-12 14:02:51 - DEBUG - token_result: ('eyJhbGciOiJIUzI1NiIsInR5cCI6IkpXVCJ9.eyJzdWIiOiJ1c2VyMSIsInBlcm1pc3Npb24iOjEsImV4cCI6MTc0MjE4NTMzOH0.VBJGQV2zxNg72PcrE3Zcfsqm9tSWDaHYNladSb_DZYU', '1742185338')
2025-03-12 14:02:51 - ERROR - Exception in ASGI application
Traceback (most recent call last):
  File "C:\Users\tensy\AppData\Local\Programs\Python\Python312\Lib\site-packages\uvicorn\protocols\http\h11_impl.py", line 403, in run_asgi
    result = await app(  # type: ignore[func-returns-value]
             ^^^^^^^^^^^^^^^^^^^^^^^^^^^^^^^^^^^^^^^^^^^^^^
  File "C:\Users\tensy\AppData\Local\Programs\Python\Python312\Lib\site-packages\uvicorn\middleware\proxy_headers.py", line 60, in __call__
    return await self.app(scope, receive, send)
           ^^^^^^^^^^^^^^^^^^^^^^^^^^^^^^^^^^^^
  File "C:\Users\tensy\AppData\Local\Programs\Python\Python312\Lib\site-packages\fastapi\applications.py", line 1054, in __call__
    await super().__call__(scope, receive, send)
  File "C:\Users\tensy\AppData\Local\Programs\Python\Python312\Lib\site-packages\starlette\applications.py", line 113, in __call__
    await self.middleware_stack(scope, receive, send)
  File "C:\Users\tensy\AppData\Local\Programs\Python\Python312\Lib\site-packages\starlette\middleware\errors.py", line 187, in __call__
    raise exc
  File "C:\Users\tensy\AppData\Local\Programs\Python\Python312\Lib\site-packages\starlette\middleware\errors.py", line 165, in __call__
    await self.app(scope, receive, _send)
  File "C:\Users\tensy\AppData\Local\Programs\Python\Python312\Lib\site-packages\starlette\middleware\exceptions.py", line 62, in __call__
    await wrap_app_handling_exceptions(self.app, conn)(scope, receive, send)
  File "C:\Users\tensy\AppData\Local\Programs\Python\Python312\Lib\site-packages\starlette\_exception_handler.py", line 53, in wrapped_app
    raise exc
  File "C:\Users\tensy\AppData\Local\Programs\Python\Python312\Lib\site-packages\starlette\_exception_handler.py", line 42, in wrapped_app
    await app(scope, receive, sender)
  File "C:\Users\tensy\AppData\Local\Programs\Python\Python312\Lib\site-packages\starlette\routing.py", line 715, in __call__
    await self.middleware_stack(scope, receive, send)
  File "C:\Users\tensy\AppData\Local\Programs\Python\Python312\Lib\site-packages\starlette\routing.py", line 735, in app
    await route.handle(scope, receive, send)
  File "C:\Users\tensy\AppData\Local\Programs\Python\Python312\Lib\site-packages\starlette\routing.py", line 288, in handle
    await self.app(scope, receive, send)
  File "C:\Users\tensy\AppData\Local\Programs\Python\Python312\Lib\site-packages\starlette\routing.py", line 76, in app
    await wrap_app_handling_exceptions(app, request)(scope, receive, send)
  File "C:\Users\tensy\AppData\Local\Programs\Python\Python312\Lib\site-packages\starlette\_exception_handler.py", line 53, in wrapped_app
    raise exc
  File "C:\Users\tensy\AppData\Local\Programs\Python\Python312\Lib\site-packages\starlette\_exception_handler.py", line 42, in wrapped_app
    await app(scope, receive, sender)
  File "C:\Users\tensy\AppData\Local\Programs\Python\Python312\Lib\site-packages\starlette\routing.py", line 73, in app
    response = await f(request)
               ^^^^^^^^^^^^^^^^
  File "C:\Users\tensy\AppData\Local\Programs\Python\Python312\Lib\site-packages\fastapi\routing.py", line 301, in app
    raw_response = await run_endpoint_function(
                   ^^^^^^^^^^^^^^^^^^^^^^^^^^^^
  File "C:\Users\tensy\AppData\Local\Programs\Python\Python312\Lib\site-packages\fastapi\routing.py", line 212, in run_endpoint_function
    return await dependant.call(**values)
           ^^^^^^^^^^^^^^^^^^^^^^^^^^^^^^
  File "C:\Obento-Test\v_0.1.6\app\utils\utils.py", line 21, in async_wrapper
    result = await func(*args, **kwargs)
             ^^^^^^^^^^^^^^^^^^^^^^^^^^^
  File "C:\Obento-Test\v_0.1.6\app\main.py", line 113, in root
    if compare_expire_date(exp):
       ^^^^^^^^^^^^^^^^^^^^^^^^
  File "C:\Obento-Test\v_0.1.6\app\utils\utils.py", line 30, in sync_wrapper
    result = func(*args, **kwargs)
             ^^^^^^^^^^^^^^^^^^^^^
  File "C:\Obento-Test\v_0.1.6\app\utils\utils.py", line 188, in compare_expire_date
    max_age = convert_expires_to_max_age(exp_unix_str)
              ^^^^^^^^^^^^^^^^^^^^^^^^^^^^^^^^^^^^^^^^
  File "C:\Obento-Test\v_0.1.6\app\utils\utils.py", line 298, in convert_expires_to_max_age
    expires_datetime = parser.isoparse(expires).replace(tzinfo=timezone.utc)
                       ^^^^^^^^^^^^^^^^^^^^^^^^
  File "C:\Users\tensy\AppData\Local\Programs\Python\Python312\Lib\site-packages\dateutil\parser\isoparser.py", line 37, in func
    return f(self, str_in, *args, **kwargs)
           ^^^^^^^^^^^^^^^^^^^^^^^^^^^^^^^^
  File "C:\Users\tensy\AppData\Local\Programs\Python\Python312\Lib\site-packages\dateutil\parser\isoparser.py", line 138, in isoparse
    components += self._parse_isotime(dt_str[pos + 1:])
                  ^^^^^^^^^^^^^^^^^^^^^^^^^^^^^^^^^^^^^
  File "C:\Users\tensy\AppData\Local\Programs\Python\Python312\Lib\site-packages\dateutil\parser\isoparser.py", line 337, in _parse_isotime
    raise ValueError('ISO time too short')
ValueError: ISO time too short
2025-03-12 14:04:12 - INFO - root() - ルートにアクセスしました
2025-03-12 14:04:12 - DEBUG - token_result: None
2025-03-12 14:04:12 - DEBUG - token_result: ありません
2025-03-12 14:04:13 - INFO - root() - ルートにアクセスしました
2025-03-12 14:04:13 - DEBUG - token_result: None
2025-03-12 14:04:13 - DEBUG - token_result: ありません
2025-03-12 14:09:23 - INFO - root() - ルートにアクセスしました
2025-03-12 14:09:23 - DEBUG - token_result: None
2025-03-12 14:09:23 - DEBUG - token_result: ありません
2025-03-12 14:09:25 - INFO - root() - ルートにアクセスしました
2025-03-12 14:09:25 - DEBUG - token_result: None
2025-03-12 14:09:25 - DEBUG - token_result: ありません
2025-03-12 14:11:10 - INFO - root() - ルートにアクセスしました
2025-03-12 14:11:10 - DEBUG - token_result: None
2025-03-12 14:11:10 - DEBUG - token_result: ありません
2025-03-12 14:21:20 - INFO - Started server process [15072]
2025-03-12 14:21:20 - INFO - Waiting for application startup.
2025-03-12 14:21:20 - INFO - Application startup complete.
2025-03-12 14:21:20 - INFO - Uvicorn running on https://192.168.3.19:8000 (Press CTRL+C to quit)
2025-03-12 14:21:21 - INFO - root() - ルートにアクセスしました
2025-03-12 14:21:21 - DEBUG - token_result: eyJhbGciOiJIUzI1NiIsInR5cCI6IkpXVCJ9.eyJzdWIiOiJ1c2VyMSIsInBlcm1pc3Npb24iOjEsImV4cCI6MTc0MjE4NTMzOH0.VBJGQV2zxNg72PcrE3Zcfsqm9tSWDaHYNladSb_DZYU
2025-03-12 14:21:21 - DEBUG - exp_result: 1742185338
2025-03-12 14:21:21 - ERROR - Exception in ASGI application
Traceback (most recent call last):
  File "C:\Users\tensy\AppData\Local\Programs\Python\Python312\Lib\site-packages\uvicorn\protocols\http\h11_impl.py", line 403, in run_asgi
    result = await app(  # type: ignore[func-returns-value]
             ^^^^^^^^^^^^^^^^^^^^^^^^^^^^^^^^^^^^^^^^^^^^^^
  File "C:\Users\tensy\AppData\Local\Programs\Python\Python312\Lib\site-packages\uvicorn\middleware\proxy_headers.py", line 60, in __call__
    return await self.app(scope, receive, send)
           ^^^^^^^^^^^^^^^^^^^^^^^^^^^^^^^^^^^^
  File "C:\Users\tensy\AppData\Local\Programs\Python\Python312\Lib\site-packages\fastapi\applications.py", line 1054, in __call__
    await super().__call__(scope, receive, send)
  File "C:\Users\tensy\AppData\Local\Programs\Python\Python312\Lib\site-packages\starlette\applications.py", line 113, in __call__
    await self.middleware_stack(scope, receive, send)
  File "C:\Users\tensy\AppData\Local\Programs\Python\Python312\Lib\site-packages\starlette\middleware\errors.py", line 187, in __call__
    raise exc
  File "C:\Users\tensy\AppData\Local\Programs\Python\Python312\Lib\site-packages\starlette\middleware\errors.py", line 165, in __call__
    await self.app(scope, receive, _send)
  File "C:\Users\tensy\AppData\Local\Programs\Python\Python312\Lib\site-packages\starlette\middleware\exceptions.py", line 62, in __call__
    await wrap_app_handling_exceptions(self.app, conn)(scope, receive, send)
  File "C:\Users\tensy\AppData\Local\Programs\Python\Python312\Lib\site-packages\starlette\_exception_handler.py", line 53, in wrapped_app
    raise exc
  File "C:\Users\tensy\AppData\Local\Programs\Python\Python312\Lib\site-packages\starlette\_exception_handler.py", line 42, in wrapped_app
    await app(scope, receive, sender)
  File "C:\Users\tensy\AppData\Local\Programs\Python\Python312\Lib\site-packages\starlette\routing.py", line 715, in __call__
    await self.middleware_stack(scope, receive, send)
  File "C:\Users\tensy\AppData\Local\Programs\Python\Python312\Lib\site-packages\starlette\routing.py", line 735, in app
    await route.handle(scope, receive, send)
  File "C:\Users\tensy\AppData\Local\Programs\Python\Python312\Lib\site-packages\starlette\routing.py", line 288, in handle
    await self.app(scope, receive, send)
  File "C:\Users\tensy\AppData\Local\Programs\Python\Python312\Lib\site-packages\starlette\routing.py", line 76, in app
    await wrap_app_handling_exceptions(app, request)(scope, receive, send)
  File "C:\Users\tensy\AppData\Local\Programs\Python\Python312\Lib\site-packages\starlette\_exception_handler.py", line 53, in wrapped_app
    raise exc
  File "C:\Users\tensy\AppData\Local\Programs\Python\Python312\Lib\site-packages\starlette\_exception_handler.py", line 42, in wrapped_app
    await app(scope, receive, sender)
  File "C:\Users\tensy\AppData\Local\Programs\Python\Python312\Lib\site-packages\starlette\routing.py", line 73, in app
    response = await f(request)
               ^^^^^^^^^^^^^^^^
  File "C:\Users\tensy\AppData\Local\Programs\Python\Python312\Lib\site-packages\fastapi\routing.py", line 301, in app
    raw_response = await run_endpoint_function(
                   ^^^^^^^^^^^^^^^^^^^^^^^^^^^^
  File "C:\Users\tensy\AppData\Local\Programs\Python\Python312\Lib\site-packages\fastapi\routing.py", line 212, in run_endpoint_function
    return await dependant.call(**values)
           ^^^^^^^^^^^^^^^^^^^^^^^^^^^^^^
  File "C:\Obento-Test\v_0.1.6\app\utils\utils.py", line 22, in async_wrapper
    result = await func(*args, **kwargs)
             ^^^^^^^^^^^^^^^^^^^^^^^^^^^
  File "C:\Obento-Test\v_0.1.6\app\main.py", line 112, in root
    if compare_expire_date(exp):
                           ^^^
UnboundLocalError: cannot access local variable 'exp' where it is not associated with a value
2025-03-12 15:23:35 - INFO - Started server process [7432]
2025-03-12 15:23:35 - INFO - Waiting for application startup.
2025-03-12 15:23:35 - INFO - Application startup complete.
2025-03-12 15:23:35 - INFO - Uvicorn running on https://192.168.3.19:8000 (Press CTRL+C to quit)
2025-03-12 15:23:37 - INFO - root() - ルートにアクセスしました
2025-03-12 15:23:37 - DEBUG - token: eyJhbGciOiJIUzI1NiIsInR5cCI6IkpXVCJ9.eyJzdWIiOiJ1c2VyMSIsInBlcm1pc3Npb24iOjEsImV4cCI6MTc0MjE4NTMzOH0.VBJGQV2zxNg72PcrE3Zcfsqm9tSWDaHYNladSb_DZYU
2025-03-12 15:23:37 - ERROR - Exception in ASGI application
Traceback (most recent call last):
  File "C:\Users\tensy\AppData\Local\Programs\Python\Python312\Lib\site-packages\uvicorn\protocols\http\h11_impl.py", line 403, in run_asgi
    result = await app(  # type: ignore[func-returns-value]
             ^^^^^^^^^^^^^^^^^^^^^^^^^^^^^^^^^^^^^^^^^^^^^^
  File "C:\Users\tensy\AppData\Local\Programs\Python\Python312\Lib\site-packages\uvicorn\middleware\proxy_headers.py", line 60, in __call__
    return await self.app(scope, receive, send)
           ^^^^^^^^^^^^^^^^^^^^^^^^^^^^^^^^^^^^
  File "C:\Users\tensy\AppData\Local\Programs\Python\Python312\Lib\site-packages\fastapi\applications.py", line 1054, in __call__
    await super().__call__(scope, receive, send)
  File "C:\Users\tensy\AppData\Local\Programs\Python\Python312\Lib\site-packages\starlette\applications.py", line 113, in __call__
    await self.middleware_stack(scope, receive, send)
  File "C:\Users\tensy\AppData\Local\Programs\Python\Python312\Lib\site-packages\starlette\middleware\errors.py", line 187, in __call__
    raise exc
  File "C:\Users\tensy\AppData\Local\Programs\Python\Python312\Lib\site-packages\starlette\middleware\errors.py", line 165, in __call__
    await self.app(scope, receive, _send)
  File "C:\Users\tensy\AppData\Local\Programs\Python\Python312\Lib\site-packages\starlette\middleware\exceptions.py", line 62, in __call__
    await wrap_app_handling_exceptions(self.app, conn)(scope, receive, send)
  File "C:\Users\tensy\AppData\Local\Programs\Python\Python312\Lib\site-packages\starlette\_exception_handler.py", line 53, in wrapped_app
    raise exc
  File "C:\Users\tensy\AppData\Local\Programs\Python\Python312\Lib\site-packages\starlette\_exception_handler.py", line 42, in wrapped_app
    await app(scope, receive, sender)
  File "C:\Users\tensy\AppData\Local\Programs\Python\Python312\Lib\site-packages\starlette\routing.py", line 715, in __call__
    await self.middleware_stack(scope, receive, send)
  File "C:\Users\tensy\AppData\Local\Programs\Python\Python312\Lib\site-packages\starlette\routing.py", line 735, in app
    await route.handle(scope, receive, send)
  File "C:\Users\tensy\AppData\Local\Programs\Python\Python312\Lib\site-packages\starlette\routing.py", line 288, in handle
    await self.app(scope, receive, send)
  File "C:\Users\tensy\AppData\Local\Programs\Python\Python312\Lib\site-packages\starlette\routing.py", line 76, in app
    await wrap_app_handling_exceptions(app, request)(scope, receive, send)
  File "C:\Users\tensy\AppData\Local\Programs\Python\Python312\Lib\site-packages\starlette\_exception_handler.py", line 53, in wrapped_app
    raise exc
  File "C:\Users\tensy\AppData\Local\Programs\Python\Python312\Lib\site-packages\starlette\_exception_handler.py", line 42, in wrapped_app
    await app(scope, receive, sender)
  File "C:\Users\tensy\AppData\Local\Programs\Python\Python312\Lib\site-packages\starlette\routing.py", line 73, in app
    response = await f(request)
               ^^^^^^^^^^^^^^^^
  File "C:\Users\tensy\AppData\Local\Programs\Python\Python312\Lib\site-packages\fastapi\routing.py", line 301, in app
    raw_response = await run_endpoint_function(
                   ^^^^^^^^^^^^^^^^^^^^^^^^^^^^
  File "C:\Users\tensy\AppData\Local\Programs\Python\Python312\Lib\site-packages\fastapi\routing.py", line 212, in run_endpoint_function
    return await dependant.call(**values)
           ^^^^^^^^^^^^^^^^^^^^^^^^^^^^^^
  File "C:\Obento-Test\v_0.1.6\app\utils\utils.py", line 23, in async_wrapper
    result = await func(*args, **kwargs)
             ^^^^^^^^^^^^^^^^^^^^^^^^^^^
  File "C:\Obento-Test\v_0.1.6\app\main.py", line 95, in root
    max_age = get_max_age(request)
              ^^^^^^^^^^^^^^^^^^^^
  File "C:\Obento-Test\v_0.1.6\app\utils\utils.py", line 32, in sync_wrapper
    result = func(*args, **kwargs)
             ^^^^^^^^^^^^^^^^^^^^^
  File "C:\Obento-Test\v_0.1.6\app\utils\utils.py", line 269, in get_max_age
    return int(max_age)
           ^^^^^^^^^^^^
ValueError: invalid literal for int() with base 10: ''
2025-03-12 15:24:53 - INFO - Started server process [9616]
2025-03-12 15:24:53 - INFO - Waiting for application startup.
2025-03-12 15:24:53 - INFO - Application startup complete.
2025-03-12 15:24:53 - INFO - Uvicorn running on https://192.168.3.19:8000 (Press CTRL+C to quit)
2025-03-12 15:24:54 - INFO - root() - ルートにアクセスしました
2025-03-12 15:24:54 - DEBUG - token: eyJhbGciOiJIUzI1NiIsInR5cCI6IkpXVCJ9.eyJzdWIiOiJ1c2VyMSIsInBlcm1pc3Npb24iOjEsImV4cCI6MTc0MjE4NTMzOH0.VBJGQV2zxNg72PcrE3Zcfsqm9tSWDaHYNladSb_DZYU
2025-03-12 15:24:54 - ERROR - Exception in ASGI application
Traceback (most recent call last):
  File "C:\Users\tensy\AppData\Local\Programs\Python\Python312\Lib\site-packages\uvicorn\protocols\http\h11_impl.py", line 403, in run_asgi
    result = await app(  # type: ignore[func-returns-value]
             ^^^^^^^^^^^^^^^^^^^^^^^^^^^^^^^^^^^^^^^^^^^^^^
  File "C:\Users\tensy\AppData\Local\Programs\Python\Python312\Lib\site-packages\uvicorn\middleware\proxy_headers.py", line 60, in __call__
    return await self.app(scope, receive, send)
           ^^^^^^^^^^^^^^^^^^^^^^^^^^^^^^^^^^^^
  File "C:\Users\tensy\AppData\Local\Programs\Python\Python312\Lib\site-packages\fastapi\applications.py", line 1054, in __call__
    await super().__call__(scope, receive, send)
  File "C:\Users\tensy\AppData\Local\Programs\Python\Python312\Lib\site-packages\starlette\applications.py", line 113, in __call__
    await self.middleware_stack(scope, receive, send)
  File "C:\Users\tensy\AppData\Local\Programs\Python\Python312\Lib\site-packages\starlette\middleware\errors.py", line 187, in __call__
    raise exc
  File "C:\Users\tensy\AppData\Local\Programs\Python\Python312\Lib\site-packages\starlette\middleware\errors.py", line 165, in __call__
    await self.app(scope, receive, _send)
  File "C:\Users\tensy\AppData\Local\Programs\Python\Python312\Lib\site-packages\starlette\middleware\exceptions.py", line 62, in __call__
    await wrap_app_handling_exceptions(self.app, conn)(scope, receive, send)
  File "C:\Users\tensy\AppData\Local\Programs\Python\Python312\Lib\site-packages\starlette\_exception_handler.py", line 53, in wrapped_app
    raise exc
  File "C:\Users\tensy\AppData\Local\Programs\Python\Python312\Lib\site-packages\starlette\_exception_handler.py", line 42, in wrapped_app
    await app(scope, receive, sender)
  File "C:\Users\tensy\AppData\Local\Programs\Python\Python312\Lib\site-packages\starlette\routing.py", line 715, in __call__
    await self.middleware_stack(scope, receive, send)
  File "C:\Users\tensy\AppData\Local\Programs\Python\Python312\Lib\site-packages\starlette\routing.py", line 735, in app
    await route.handle(scope, receive, send)
  File "C:\Users\tensy\AppData\Local\Programs\Python\Python312\Lib\site-packages\starlette\routing.py", line 288, in handle
    await self.app(scope, receive, send)
  File "C:\Users\tensy\AppData\Local\Programs\Python\Python312\Lib\site-packages\starlette\routing.py", line 76, in app
    await wrap_app_handling_exceptions(app, request)(scope, receive, send)
  File "C:\Users\tensy\AppData\Local\Programs\Python\Python312\Lib\site-packages\starlette\_exception_handler.py", line 53, in wrapped_app
    raise exc
  File "C:\Users\tensy\AppData\Local\Programs\Python\Python312\Lib\site-packages\starlette\_exception_handler.py", line 42, in wrapped_app
    await app(scope, receive, sender)
  File "C:\Users\tensy\AppData\Local\Programs\Python\Python312\Lib\site-packages\starlette\routing.py", line 73, in app
    response = await f(request)
               ^^^^^^^^^^^^^^^^
  File "C:\Users\tensy\AppData\Local\Programs\Python\Python312\Lib\site-packages\fastapi\routing.py", line 301, in app
    raw_response = await run_endpoint_function(
                   ^^^^^^^^^^^^^^^^^^^^^^^^^^^^
  File "C:\Users\tensy\AppData\Local\Programs\Python\Python312\Lib\site-packages\fastapi\routing.py", line 212, in run_endpoint_function
    return await dependant.call(**values)
           ^^^^^^^^^^^^^^^^^^^^^^^^^^^^^^
  File "C:\Obento-Test\v_0.1.6\app\utils\utils.py", line 23, in async_wrapper
    result = await func(*args, **kwargs)
             ^^^^^^^^^^^^^^^^^^^^^^^^^^^
  File "C:\Obento-Test\v_0.1.6\app\main.py", line 95, in root
    max_age = get_max_age(request)
              ^^^^^^^^^^^^^^^^^^^^
  File "C:\Obento-Test\v_0.1.6\app\utils\utils.py", line 32, in sync_wrapper
    result = func(*args, **kwargs)
             ^^^^^^^^^^^^^^^^^^^^^
  File "C:\Obento-Test\v_0.1.6\app\utils\utils.py", line 267, in get_max_age
    max_age_int = int(max_age)
                  ^^^^^^^^^^^^
ValueError: invalid literal for int() with base 10: ''
